Workbook

Sheet BOM
A1: Summon Desk - Bill of Materials
A2: Version 6: UPS instead of the Anker, no desk lowering (no Humanscale wiring), plug-in charging station with a breakaway cord and interlock. Based on your wiring diagram. All prices USD. Blue = inputs you can edit (Qty, Unit price). Black = formulas. "Verified" = price seen this session at the source shown; "Estimate" = my estimate, check before ordering.
A4: # | B4: Category | C4: Item | D4: Part / model | E4: Qty | F4: Unit price ($) | G4: Extended ($) | H4: Status | I4: Price status | J4: Source / where to buy | K4: Notes
A5: 1 | B5: Swerve drive base | C5: 3in MAXSwerve Module | D5: REV-21-3005 | E5: 4 | F5: 240 | G5: =E5*F5 -> 960 | H5: Required | I5: Estimate | J5: revrobotics.com | K5: Confirm what the module kit includes (encoder, gears, wheel). Module weighs 3.8 lb with the NEO (REV). REV publishes no load rating that I could find, and its wheels are consumables that wear faster with robot weight, so check with REV for your loaded mass and test on your real floors.
A6: 2 | B6: Swerve drive base | C6: NEO Brushless Motor V1.1 (drive) | D6: REV | E6: 4 | F6: 45 | G6: =E6*F6 -> 180 | H6: Required | I6: Estimate | J6: revrobotics.com
A7: 3 | B7: Swerve drive base | C7: NEO 550 Brushless Motor (steer) | D7: REV | E7: 4 | F7: 30 | G7: =E7*F7 -> 120 | H7: Required | I7: Estimate | J7: revrobotics.com
A8: 4 | B8: Swerve drive base | C8: SPARK MAX Motor Controller | D8: REV-11-2158 | E8: 8 | F8: 90 | G8: =E8*F8 -> 720 | H8: Required | I8: Estimate | J8: revrobotics.com | K8: 2 per module (drive + steer), per your wiring diagram.
A9: 5 | B9: Swerve drive base | C9: Through Bore Encoder + Absolute Encoder Adapter | D9: REV | E9: 4 | F9: 40 | G9: =E9*F9 -> 160 | H9: Required | I9: Estimate | J9: revrobotics.com | K9: Per diagram: encoder on the steer SPARK. Skip if the module kit already includes it.
A10: 6 | B10: Swerve drive base | C10: Spare wheel tread / gearing | D10: REV | E10: 1 | F10: 60 | G10: =E10*F10 -> 60 | H10: Optional | I10: Estimate | J10: revrobotics.com
A11: 7 | B11: Control system & 12 V power | C11: roboRIO 2.0 | D11: NI / AndyMark am-3000a | E11: 1 | F11: 550 | G11: =E11*F11 -> 550 | H11: Required | I11: Estimate | J11: andymark.com/products/ni-roborio-2-0 | K11: AndyMark sells it only for FRC use; non-FRC buyers must contact NI. Being replaced by Systemcore (WPILib 2027 drops roboRIO). See Alt options.
A12: 8 | B12: Control system & 12 V power | C12: Power Distribution Hub (PDH) | D12: REV | E12: 1 | F12: 85 | G12: =E12*F12 -> 85 | H12: Required | I12: Estimate | J12: revrobotics.com | K12: Diagram shows PDP/PDH.
A13: 9 | B13: Control system & 12 V power | C13: Main breaker 120 A | D13: FRC-style (Cooper Bussmann) | E13: 1 | F13: 25 | G13: =E13*F13 -> 25 | H13: Required | I13: Estimate | J13: andymark.com / revrobotics.com | K13: Manual breaker only: no remote-trip coil. E-stop needs the contactor below.
A14: 10 | B14: Control system & 12 V power | C14: 12 V SLA battery (MK ES17-12 class) | D14: MK ES17-12 | E14: 2 | F14: 50 | G14: =E14*F14 -> 100 | H14: Required | I14: Estimate | J14: revrobotics.com / andymark.com | K14: 1 in use + 1 spare/rotation.
A15: 11 | B15: Control system & 12 V power | C15: 12 V SLA smart charger (>=10 A) | D15: Battery Tender / FRC charger class | E15: 1 | F15: 60 | G15: =E15*F15 -> 60 | H15: Required | I15: Estimate | J15: various | K15: Dock charging for the SLA: see Charging dock sheet notes.
A16: 12 | B16: Control system & 12 V power | C16: FRC radio or standard Wi-Fi router | D16: OM5P-AC / REV radio / consumer router | E16: 1 | F16: 150 | G16: =E16*F16 -> 150 | H16: Required | I16: Estimate | J16: various | K16: A plain router is cheaper if you are not using FRC field equipment.
A17: 13 | B17: Control system & 12 V power | C17: 5-port managed Ethernet switch | E17: 1 | F17: 30 | G17: =E17*F17 -> 30 | H17: Required | I17: Estimate | J17: various | K17: RoboRIO + onboard computer + lidars on one subnet.
A18: 14 | B18: Control system & 12 V power | C18: Wire & connector kit (6-12 AWG, Anderson, ferrules, WAGO) | E18: 1 | F18: 120 | G18: =E18*F18 -> 120 | H18: Required | I18: Estimate | J18: various
A19: 15 | B19: Control system & 12 V power | C19: Gamepad controller for teleop testing | E19: 1 | F19: 30 | G19: =E19*F19 -> 30 | H19: Required | I19: Estimate | J19: various | K19: Needed to drive the base by hand in the early stages. Assumes a laptop for the Driver Station is already owned.
A20: 16 | B20: Control system & 12 V power | C20: Robot Signal Light | E20: 1 | F20: 12 | G20: =E20*F20 -> 12 | H20: Optional | I20: Estimate | J20: various | K20: FRC convention; useful status indicator.
A21: 17 | B21: Control system & 12 V power | C21: IMU (BNO085 breakout or navX2) | E21: 1 | F21: 60 | G21: =E21*F21 -> 60 | H21: Required | I21: Estimate | J21: various | K21: Midpoint of ~$25 (BNO085) to ~$100 (navX2).
A22: 18 | B22: Onboard compute & perception | C22: Raspberry Pi 5 8 GB (or Jetson Orin Nano) | E22: 1 | F22: 150 | G22: =E22*F22 -> 150 | H22: Required | I22: Estimate | J22: various | K22: Memory prices are volatile in 2026; a forum post reports the 4 GB Pi 5 at ~$110 vs $60 at launch. Check current price.
A23: 19 | B23: Onboard compute & perception | C23: Pi accessories: active cooler, 27 W PD supply, NVMe HAT + 256 GB SSD | E23: 1 | F23: 90 | G23: =E23*F23 -> 90 | H23: Required | I23: Estimate | J23: various
A24: 20 | B24: Onboard compute & perception | C24: 2D 360-degree lidar (RPLIDAR A2-class) | D24: Slamtec RPLIDAR A2-class | E24: 2 | F24: 330 | G24: =E24*F24 -> 660 | H24: Required | I24: Estimate | J24: slamtec.com / resellers | K24: Two, corner-mounted per diagram. Cheaper LD19-class units exist (~$80-100): see Alt options.
A25: 21 | B25: Onboard compute & perception | C25: USB / serial cables and hub | E25: 1 | F25: 25 | G25: =E25*F25 -> 25 | H25: Required | I25: Estimate | J25: various
A26: 22 | B26: Onboard compute & perception | C26: Camera for dock alignment (Pi Camera Module 3) | E26: 1 | F26: 30 | G26: =E26*F26 -> 30 | H26: Recommended | I26: Estimate | J26: various | K26: AprilTag / marker detection for final docking approach.
A27: 23 | B27: Onboard compute & perception | C27: Depth camera for desktop-height obstacles and people (OAK-D Lite / RealSense) | E27: 1 | F27: 200 | G27: =E27*F27 -> 200 | H27: Recommended | I27: Estimate | J27: various | K27: Now recommended: the desk always drives at standing height, and a lidar mounted low on the frame cannot see shelves, chair backs or desk edges at desktop height. Alternatives: a second lidar plane at desktop height.
A28: 24 | B28: Humanscale desk integration | C28: Humanscale electric sit-stand table (eFloat family), used MANUALLY | D28: Existing | E28: 1 | F28: 0 | G28: =E28*F28 -> 0 | H28: Existing | I28: n/a | J28: humanscale.com/products/standing-desks/efloat-lite-table | K28: Assumed already owned: $0, excluded from totals. No wiring into its controls: you raise and lower it yourself. Confirm model and rated load.
A29: 25 | B29: Humanscale desk integration | C29: Height sensor, read-only (VL53L1X time-of-flight breakout) | D29: Pololu / Adafruit | E29: 1 | F29: 15 | G29: =E29*F29 -> 15 | H29: Optional | I29: Estimate | J29: Pololu / Adafruit | K29: Not wired into the Humanscale. It only lets software cap speed when the desk is left tall, since the desk no longer lowers before driving.
A30: 26 | B30: House power (UPS) | C30: Line-interactive UPS, pure sine wave, ~1000-1500 VA, USB monitoring | D30: APC / CyberPower / Eaton class | E30: 1 | F30: 300 | G30: =E30*F30 -> 300 | H30: Required | I30: Estimate | J30: various | K30: Replaces the Anker. Powers the computer, lidars and desk. Charges itself whenever it has wall power. Check weight (sealed lead-acid units are heavy but far lighter than the Anker), battery watt-hours, and that its USB reporting is supported by NUT.
A31: 27 | B31: House power (UPS) | C31: UPS mounting bracket under the desktop (through-bolts, backing plates, vibration isolation) | E31: 1 | F31: 60 | G31: =E31*F31 -> 60 | H31: Required | I31: Estimate | J31: fabricate | K31: Your plan: bolt the UPS to the underside of the desktop. Check the top is thick and strong enough (use backing plates, not screws into the surface), add cable slack for height changes, and keep the UPS vents clear. A UPS is not designed to ride on a moving base, so isolate it from shock.
A32: 28 | B32: House power (UPS) | C32: DC-DC buck 12 V to 5 V (10 A) | E32: 1 | F32: 20 | G32: =E32*F32 -> 20 | H32: Required | I32: Estimate | J32: various
A33: 29 | B33: House power (UPS) | C33: Fuses / breakers with holders (ATO / MIDI) | E33: 1 | F33: 30 | G33: =E33*F33 -> 30 | H33: Required | I33: Estimate | J33: various
A34: 30 | B34: House power (UPS) | C34: GFCI AC distribution + cords | E34: 1 | F34: 40 | G34: =E34*F34 -> 40 | H34: Required | I34: Estimate | J34: various | K34: Mains voltage inside the base: use proper strain relief and enclosures.
A35: 31 | B35: E-stop & safety | C35: 22 mm E-stop pushbutton (twist-release, NC) | E35: 2 | F35: 25 | G35: =E35*F35 -> 50 | H35: Required | I35: Estimate | J35: various | K35: One on desktop, one on the frame exterior (per diagram), in series.
A36: 32 | B36: E-stop & safety | C36: 12 V DC contactor, >=150 A (battery positive) | D36: Albright SW-series class | E36: 1 | F36: 110 | G36: =E36*F36 -> 110 | H36: Required | I36: Estimate | J36: various | K36: Replaces the diagram's "main breaker coil" (a standard FRC breaker cannot be tripped remotely). Verify rating.
A37: 33 | B37: E-stop & safety | C37: Dual-channel safety relay (E-stop monitoring) | D37: Pilz / Schneider / Omron class | E37: 1 | F37: 180 | G37: =E37*F37 -> 180 | H37: Recommended | I37: Estimate | J37: various
A38: 34 | B38: E-stop & safety | C38: Contact bumper / safety-edge strips | E38: 1 | F38: 150 | G38: =E38*F38 -> 150 | H38: Recommended | I38: Estimate | J38: various | K38: Last-resort contact detection around the frame.
A39: 35 | B39: E-stop & safety | C39: Amber beacon + buzzer (12 V) | E39: 1 | F39: 25 | G39: =E39*F39 -> 25 | H39: Recommended | I39: Estimate | J39: various | K39: Tells people it is moving.
A40: 36 | B40: Charging dock | C40: Dock marks / simple guide so the desk parks within cord reach | E40: 1 | F40: 40 | G40: =E40*F40 -> 40 | H40: Recommended | I40: Estimate | J40: fabricate | K40: With a manual cord the desk only has to stop near the wall station, not align to the millimeter.
A41: 37 | B41: Charging dock | C41: GFCI wall outlet on its own 15 A circuit (electrician) | E41: 1 | F41: 60 | G41: =E41*F41 -> 60 | H41: Required | I41: Estimate | J41: electrician | K41: The charging station. Keep it on a circuit that is not shared with big loads.
...

Sheet Summary
A1: Cost summary
A2: Sums come from the BOM sheet. Change the yellow cell to adjust contingency.
A4: Category | B4: Required ($) | C4: Recommended ($) | D4: Optional ($) | E4: Category total ($)
A5: Swerve drive base | B5: =SUMIFS(BOM!$G$5:$G$59,BOM!$B$5:$B$59,$A5,BOM!$H$5:$H$59,"Required") -> 2140 | C5: =SUMIFS(BOM!$G$5:$G$59,BOM!$B$5:$B$59,$A5,BOM!$H$5:$H$59,"Recommended") -> 0 | D5: =SUMIFS(BOM!$G$5:$G$59,BOM!$B$5:$B$59,$A5,BOM!$H$5:$H$59,"Optional") -> 60 | E5: =SUM(B5:D5) -> 2200
A6: Control system & 12 V power | B6: =SUMIFS(BOM!$G$5:$G$59,BOM!$B$5:$B$59,$A6,BOM!$H$5:$H$59,"Required") -> 1210 | C6: =SUMIFS(BOM!$G$5:$G$59,BOM!$B$5:$B$59,$A6,BOM!$H$5:$H$59,"Recommended") -> 0 | D6: =SUMIFS(BOM!$G$5:$G$59,BOM!$B$5:$B$59,$A6,BOM!$H$5:$H$59,"Optional") -> 12 | E6: =SUM(B6:D6) -> 1222
A7: Onboard compute & perception | B7: =SUMIFS(BOM!$G$5:$G$59,BOM!$B$5:$B$59,$A7,BOM!$H$5:$H$59,"Required") -> 925 | C7: =SUMIFS(BOM!$G$5:$G$59,BOM!$B$5:$B$59,$A7,BOM!$H$5:$H$59,"Recommended") -> 230 | D7: =SUMIFS(BOM!$G$5:$G$59,BOM!$B$5:$B$59,$A7,BOM!$H$5:$H$59,"Optional") -> 0 | E7: =SUM(B7:D7) -> 1155
A8: Humanscale desk integration | B8: =SUMIFS(BOM!$G$5:$G$59,BOM!$B$5:$B$59,$A8,BOM!$H$5:$H$59,"Required") -> 0 | C8: =SUMIFS(BOM!$G$5:$G$59,BOM!$B$5:$B$59,$A8,BOM!$H$5:$H$59,"Recommended") -> 0 | D8: =SUMIFS(BOM!$G$5:$G$59,BOM!$B$5:$B$59,$A8,BOM!$H$5:$H$59,"Optional") -> 15 | E8: =SUM(B8:D8) -> 15
A9: House power (UPS) | B9: =SUMIFS(BOM!$G$5:$G$59,BOM!$B$5:$B$59,$A9,BOM!$H$5:$H$59,"Required") -> 450 | C9: =SUMIFS(BOM!$G$5:$G$59,BOM!$B$5:$B$59,$A9,BOM!$H$5:$H$59,"Recommended") -> 0 | D9: =SUMIFS(BOM!$G$5:$G$59,BOM!$B$5:$B$59,$A9,BOM!$H$5:$H$59,"Optional") -> 0 | E9: =SUM(B9:D9) -> 450
A10: E-stop & safety | B10: =SUMIFS(BOM!$G$5:$G$59,BOM!$B$5:$B$59,$A10,BOM!$H$5:$H$59,"Required") -> 160 | C10: =SUMIFS(BOM!$G$5:$G$59,BOM!$B$5:$B$59,$A10,BOM!$H$5:$H$59,"Recommended") -> 355 | D10: =SUMIFS(BOM!$G$5:$G$59,BOM!$B$5:$B$59,$A10,BOM!$H$5:$H$59,"Optional") -> 0 | E10: =SUM(B10:D10) -> 515
A11: Charging dock | B11: =SUMIFS(BOM!$G$5:$G$59,BOM!$B$5:$B$59,$A11,BOM!$H$5:$H$59,"Required") -> 230 | C11: =SUMIFS(BOM!$G$5:$G$59,BOM!$B$5:$B$59,$A11,BOM!$H$5:$H$59,"Recommended") -> 87 | D11: =SUMIFS(BOM!$G$5:$G$59,BOM!$B$5:$B$59,$A11,BOM!$H$5:$H$59,"Optional") -> 40 | E11: =SUM(B11:D11) -> 357
A12: Frame & mechanical | B12: =SUMIFS(BOM!$G$5:$G$59,BOM!$B$5:$B$59,$A12,BOM!$H$5:$H$59,"Required") -> 650 | C12: =SUMIFS(BOM!$G$5:$G$59,BOM!$B$5:$B$59,$A12,BOM!$H$5:$H$59,"Recommended") -> 100 | D12: =SUMIFS(BOM!$G$5:$G$59,BOM!$B$5:$B$59,$A12,BOM!$H$5:$H$59,"Optional") -> 0 | E12: =SUM(B12:D12) -> 750
A13: Miscellaneous | B13: =SUMIFS(BOM!$G$5:$G$59,BOM!$B$5:$B$59,$A13,BOM!$H$5:$H$59,"Required") -> 100 | C13: =SUMIFS(BOM!$G$5:$G$59,BOM!$B$5:$B$59,$A13,BOM!$H$5:$H$59,"Recommended") -> 99 | D13: =SUMIFS(BOM!$G$5:$G$59,BOM!$B$5:$B$59,$A13,BOM!$H$5:$H$59,"Optional") -> 0 | E13: =SUM(B13:D13) -> 199
A14: Total | B14: =SUM(B5:B13) -> 5865 | C14: =SUM(C5:C13) -> 871 | D14: =SUM(D5:D13) -> 127 | E14: =SUM(E5:E13) -> 6863
A16: Build estimate
A17: Required items only | B17: =B14 -> 5865
A18: Required + Recommended (my suggested build) | B18: =B14+C14 -> 6736
A19: Contingency (% of suggested build) | B19: 0.15 | C19: Assumption: 15% covers price drift, shipping surprises and re-buys on a first-of-its-kind build. Set your own.
A20: Contingency amount | B20: =B18*B19 -> 1010.4
A21: Estimated budget (suggested build + contingency) | B21: =B18+B20 -> 7746.4
A22: Optional items, if you want them all | B22: =D14 -> 127
A24: Shares of the suggested build
A25: UPS as % of required + recommended | B25: =BOM!G30/B18 -> 0.044536817
A26: Swerve drive base as % of required + recommended | B26: =(SUMIFS(BOM!$G$5:$G$59,BOM!$B$5:$B$59,"Swerve drive base"))/B18 -> 0.32660333
A28: Not included: sales tax, shipping, tools and test equipment beyond the logic analyzer, your labor, the Humanscale table (assumed owned), any electrician or machining services beyond the lines above.

Sheet Alt options
A1: Decisions that change the BOM
A2: Dollar figures here are rough estimates for comparison only. Verify before deciding.
A4: Decision | B4: Option in your diagram | C4: Alternative | D4: Effect on cost / mass / risk
A5: House power | B5: Line-interactive UPS (current plan): roughly 10-15 kg for a sealed lead-acid ~1500 VA unit (verify), ~$300. | C5: (a) A lithium (LiFePO4) UPS: lighter, longer life, costs more. (b) A larger UPS if you will power a monitor or laptop from it. | D5: Check watt-hours, not VA: UPS runtime ratings assume a short backup. Expect hours at the computer-and-lidar load, but add up your real loads. Pure sine wave output is safer for the desk motors. The earlier Anker F3800 choice (~60 kg, ~$2,500) is no longer needed.
A6: Robot controller | B6: roboRIO 2.0 (FRC-only sale via AndyMark; end of life as WPILib moves to Systemcore). | C6: (a) Systemcore when sold (price not announced); (b) CTRE Talon FX + CANivore on Pi/Jetson via SocketCAN; (c) ODrive / VESC / moteus with an open stack. | D6: Biggest architecture decision. SPARK MAX outside a roboRIO is documented as non-competition use and needs a heartbeat; Linux support is raw SocketCAN. Decide before buying motor controllers.
A7: Lidar | B7: 2x RPLIDAR A2-class (~$330 each). | C7: LD19-class 2D lidar (~$80-100 each, shorter range / lower accuracy) or one RPLIDAR plus bumpers. | D7: Saves ~$450-500. Test coverage against the desk body and Anker blind spots first.
A8: Onboard computer | B8: Raspberry Pi 5 8 GB. | C8: Jetson Orin Nano class if you add camera-based people detection. | D8: Pi is cheaper and enough for 2D lidar planning (sim planner averages a few ms). Jetson helps if you add depth cameras / neural nets.
A9: Desk interface | B9: Manual desk: no wiring into the Humanscale (current plan). The desk stays at the user's height while driving. | C9: Later, if you want automatic height: optocoupler button emulation at the handset, with a watchdog and E-stop-removed supply. | D9: Removes the optocoupler board, watchdog, logic analyzer, spare handset and the bench-test phase. New risk: the desk drives tall (higher center of gravity), so tip-over and loose items matter. Keep speeds and braking conservative and test at full height.
A10: Charging connection | B10: Not yet defined in the diagram. | C10: (1) Blind-mate shrouded mains connector into the UPS input (the UPS charges itself); (2) low-voltage dock feeding a DC charger for the 12 V battery only; (3) manual plug-in with auto-detect. | D10: (1) is simplest and supported by the UPS design, but puts mains at the dock: finger-safe, de-energized until docked, electrician review. (2) leaves the UPS to be plugged in by hand. (3) is cheapest but not automatic.
A11: Wireless charging (12 V battery) | B11: Not in the plan: an onboard charger fed from the frame inlet, with a plug. | C11: A 100 W-class wireless kit, for example the NOA CORE100 development kit (up to 100 W). Its output voltage and charge profile for AGM are not verified. | D11: Possible, but it does not remove the cord: the UPS still needs 120 V AC, so you would keep the plug and its protections. It needs much more precise parking (research systems use camera-assisted parking to sub-centimeter), wastes roughly 20% as heat, and costs more than a plain charger. Bench-test a kit with a spare AGM battery before wiring it in.

Sheet Notes & sources
A1: Assumptions, sources and open items
A3: Type | B3: Note
A4: Design change (v2) | B4: Replaced the Anker SOLIX F3800 Plus (3,840 Wh, listed ~133-137 lb, $2,499 at one reseller, previously verified) with a line-interactive UPS. The UPS price here is my ESTIMATE; your model is not known.
A5: Design change (v2) | B5: The desk no longer lowers before driving, so nothing is wired into the Humanscale controls. The optocoupler board, watchdog, logic analyzer, spare handset and extra height sensor were removed; one optional read-only height sensor remains.
A6: Verified this session | B6: AndyMark roboRIO 2.0 page: sold to FRC teams / organizers for FRC use; non-FRC inquiries go to NI. Source: https://andymark.com/products/ni-roborio-2-0
A7: Verified this session | B7: FRC community threads: WPILib 2027 will not run on roboRIO; Systemcore replaces it; Systemcore pricing not announced. Source: https://www.chiefdelphi.com/t/systemcore-onsale-date/517572
A8: Verified this session | B8: Humanscale eFloat: electric height adjustment with either a simple up/down handset or a digital memory keypad storing 4 presets. Source: https://www.thehumansolution.com/humanscale-efloat-electric-standing-desk.html and humanscale.com. No control protocol is published.
A9: Not verifiable here | B9: REV product pages loaded without prices in this session, so all REV prices are my estimates. Check revrobotics.com.
A10: Estimate | B10: All lines marked Estimate are from my general knowledge of typical prices, not a quote.
A11: Assumption | B11: You already own the Humanscale table (price $0, excluded).
A12: Assumption | B12: Quantities follow your wiring diagram: 4 swerve modules (8 SPARK MAX, 4 NEO + 4 NEO 550, 4 encoders), 2 lidars, 1 compute board, 2 E-stops. The desk board is gone in v2.
A13: Open item | B13: Whether the module kit includes the through-bore encoder / adapter.
A14: Verified this session | B14: Humanscale lift capacities (reseller / spec listings): eFloat Lite 220 lb (250 lb on angled work surfaces); eFloat Flex 225 lb (275 lb); eFloat Go 2.0 220 lb; non-electric Float 130 lb. Not confirmed whether these include the desktop. Sources: sweets.construction.com eFloat Lite/Flex listing; lttpartners.com eFloat Go 2.0 listing.
... A18: Open item | B18: Total robot mass (desk + frame + UPS + modules) and the center of gravity with the desk at standing height: size the drive, wheels and speed limits from it.
